Workbook

Sheet C Hackathon Overall Performance
A1: Sr. No. | B1: Group Name | C1: Location | D1: Total Tests | E1: Passed Tests | F1: Percentage | G1: Test Cases Evaluation Out of 60% | H1: Visteon Expert Score (out of 40) | I1: Total Score (100) | J1: Remarks
A2: 1 | B2: =_xlfn.CONCAT("GroupC",A2) -> GroupC1 | C2: Chennai | D2: 42 | E2: =VLOOKUP(B2,'Testcases evaluation'!$B$2:$E$18,3,FALSE) -> 42 | F2: =E2/D2 * 100 -> 100 | G2: =ROUND(F2*0.6,0) -> 60 | H2: 34 | I2: =SUM(G2,H2) -> 94 | J2: Best Team
A3: 2 | B3: =_xlfn.CONCAT("GroupC",A3) -> GroupC2 | C3: Chennai | D3: 42 | E3: =VLOOKUP(B3,'Testcases evaluation'!$B$2:$E$18,3,FALSE) -> 38 | F3: =E3/D3 * 100 -> 90.47619 | G3: =ROUND(F3*0.6,0) -> 54 | H3: 36 | I3: =SUM(G3,H3) -> 90
A4: 3 | B4: =_xlfn.CONCAT("GroupC",A4) -> GroupC3 | C4: Chennai | D4: 42 | E4: =VLOOKUP(B4,'Testcases evaluation'!$B$2:$E$18,3,FALSE) -> 32 | F4: =E4/D4 * 100 -> 76.190476 | G4: =ROUND(F4*0.6,0) -> 46 | H4: 34 | I4: =SUM(G4,H4) -> 80
A5: 4 | B5: =_xlfn.CONCAT("GroupC",A5) -> GroupC4 | C5: Chennai | D5: 42 | E5: =VLOOKUP(B5,'Testcases evaluation'!$B$2:$E$18,3,FALSE) -> 36 | F5: =E5/D5 * 100 -> 85.714286 | G5: =ROUND(F5*0.6,0) -> 51 | H5: 34 | I5: =SUM(G5,H5) -> 85
A6: 5 | B6: =_xlfn.CONCAT("GroupC",A6) -> GroupC5 | C6: Chennai | D6: 42 | E6: =VLOOKUP(B6,'Testcases evaluation'!$B$2:$E$18,3,FALSE) -> 40 | F6: =E6/D6 * 100 -> 95.238095 | G6: =ROUND(F6*0.6,0) -> 57 | H6: 36 | I6: =SUM(G6,H6) -> 93
A7: 6 | B7: =_xlfn.CONCAT("GroupC",A7) -> GroupC6 | C7: Chennai | D7: 42 | E7: =VLOOKUP(B7,'Testcases evaluation'!$B$2:$E$18,3,FALSE) -> 36 | F7: =E7/D7 * 100 -> 85.714286 | G7: =ROUND(F7*0.6,0) -> 51 | H7: 34 | I7: =SUM(G7,H7) -> 85
A8: 7 | B8: =_xlfn.CONCAT("GroupC",A8) -> GroupC7 | C8: Chennai | D8: 42 | E8: =VLOOKUP(B8,'Testcases evaluation'!$B$2:$E$18,3,FALSE) -> 29 | F8: =E8/D8 * 100 -> 69.047619 | G8: =ROUND(F8*0.6,0) -> 41 | H8: 34 | I8: =SUM(G8,H8) -> 75
A9: 8 | B9: =_xlfn.CONCAT("GroupC",A9) -> GroupC8 | C9: Chennai | D9: 42 | E9: =VLOOKUP(B9,'Testcases evaluation'!$B$2:$E$18,3,FALSE) -> 35 | F9: =E9/D9 * 100 -> 83.333333 | G9: =ROUND(F9*0.6,0) -> 50 | H9: 32 | I9: =SUM(G9,H9) -> 82
A10: 9 | B10: =_xlfn.CONCAT("GroupC",A10) -> GroupC9 | C10: Bangalore | D10: 42 | E10: =VLOOKUP(B10,'Testcases evaluation'!$B$2:$E$18,3,FALSE) -> 35 | F10: =E10/D10 * 100 -> 83.333333 | G10: =ROUND(F10*0.6,0) -> 50 | H10: =VLOOKUP(B10,'[1]Visteon Assessors Evaluation'!$A$2:$C$84,3,FALSE) -> 34 | I10: =SUM(G10,H10) -> 84
A11: 10 | B11: =_xlfn.CONCAT("GroupC",A11) -> GroupC10 | C11: Bangalore | D11: 42 | E11: =VLOOKUP(B11,'Testcases evaluation'!$B$2:$E$18,3,FALSE) -> 34 | F11: =E11/D11 * 100 -> 80.952381 | G11: =ROUND(F11*0.6,0) -> 49 | H11: 30 | I11: =SUM(G11,H11) -> 79
A12: 11 | B12: =_xlfn.CONCAT("GroupC",A12) -> GroupC11 | C12: Kolkata | D12: 42 | E12: =VLOOKUP(B12,'Testcases evaluation'!$B$2:$E$18,3,FALSE) -> 41 | F12: =E12/D12 * 100 -> 97.619048 | G12: =ROUND(F12*0.6,0) -> 59 | H12: 36 | I12: =SUM(G12,H12) -> 95 | J12: Best Team
A13: 12 | B13: =_xlfn.CONCAT("GroupC",A13) -> GroupC12 | C13: Kolkata | D13: 42 | E13: =VLOOKUP(B13,'Testcases evaluation'!$B$2:$E$18,3,FALSE) -> 39 | F13: =E13/D13 * 100 -> 92.857143 | G13: =ROUND(F13*0.6,0) -> 56 | H13: 36 | I13: =SUM(G13,H13) -> 92
A14: 13 | B14: =_xlfn.CONCAT("GroupC",A14) -> GroupC13 | C14: Kolkata | D14: 42 | E14: =VLOOKUP(B14,'Testcases evaluation'!$B$2:$E$18,3,FALSE) -> 37 | F14: =E14/D14 * 100 -> 88.095238 | G14: =ROUND(F14*0.6,0) -> 53 | H14: 36 | I14: =SUM(G14,H14) -> 89
A15: 14 | B15: =_xlfn.CONCAT("GroupC",A15) -> GroupC14 | C15: Kolkata | D15: 42 | E15: =VLOOKUP(B15,'Testcases evaluation'!$B$2:$E$18,3,FALSE) -> 35 | F15: =E15/D15 * 100 -> 83.333333 | G15: =ROUND(F15*0.6,0) -> 50 | H15: 38 | I15: =SUM(G15,H15) -> 88
A16: 15 | B16: =_xlfn.CONCAT("GroupC",A16) -> GroupC15 | C16: Coimbatore | D16: 42 | E16: =VLOOKUP(B16,'Testcases evaluation'!$B$2:$E$18,3,FALSE) -> 33 | F16: =E16/D16 * 100 -> 78.571429 | G16: =ROUND(F16*0.6,0) -> 47 | H16: 28 | I16: =SUM(G16,H16) -> 75
A17: 16 | B17: =_xlfn.CONCAT("GroupC",A17) -> GroupC16 | C17: Coimbatore | D17: 42 | E17: =VLOOKUP(B17,'Testcases evaluation'!$B$2:$E$18,3,FALSE) -> 33 | F17: =E17/D17 * 100 -> 78.571429 | G17: =ROUND(F17*0.6,0) -> 47 | H17: 28 | I17: =SUM(G17,H17) -> 75
A18: 17 | B18: =_xlfn.CONCAT("GroupC",A18) -> GroupC17 | C18: Trivandrum | D18: 42 | E18: =VLOOKUP(B18,'Testcases evaluation'!$B$2:$E$18,3,FALSE) -> 27 | F18: =E18/D18 * 100 -> 64.285714 | G18: =ROUND(F18*0.6,0) -> 39 | H18: 30 | I18: =SUM(G18,H18) -> 69

Sheet Visteon Experts Evaluation
A1: Hackathon GroupId | B1: Location | C1: RISER/Intern Name | D1: S.No. | E1: Evalaution Parameter | F1: Poor(Points:2) | G1: Needs Improvement (Points:4) | H1: Satisfactory(Points:6) | I1: Exceptional (Points:8) | J1: Feedback on Individual Team members | K1: Overall Feedback
A2: GroupC1 | B2: Chennai | C2: Kumar, Vivek (V.) | D2: 1 | E2: Technical Understanding | I2: 8 | J2: presentation and understanding of feature | K2: eager to explain. understands the concepts well. can focus on presenation and documentation
C3: Alekya, G Alekya (G.) | D3: 2 | E3: Teamwork / Communication | I3: 8 | J3: presentation and understanding of feature
C4: Baravkar, Aniket (A.A.) | D4: 3 | E4: Testing ability | H4: 6 | J4: presentation and understanding of feature
C5: Babu, Bhavna (B.) | D5: 4 | E5: Optimization Strategies | H5: 6 | J5: Good Communication and presentation and understanding of feature
D6: 5 | E6: Future Enhancements | H6: 6
E7: TOTAL SCORE | I7: =SUM(F2:I6) -> 34
A8: Hackathon GroupId | B8: Location | C8: RISER/Intern Name | D8: S.No. | E8: Evalaution Parameter | F8: Poor(Points:2) | G8: Needs Improvement (Points:4) | H8: Satisfactory(Points:6) | I8: Exceptional (Points:8) | J8: Feedback on Individual Team members | K8: Overall Feedback
A9: GroupC2 | B9: Chennai | C9: Zubair, Mohammed (M.) | D9: 1 | E9: Technical Understanding | I9: 8 | J9: Good Presentation and explanation of workflow | K9: Good presentation and technical understanding. strong in concepts
C10: Ganesh, Pavithra (P.) | D10: 2 | E10: Teamwork / Communication | I10: 8 | J10: Good Presentation and explanation of workflow
C11: Tipathi, Tejas (T.) | D11: 3 | E11: Testing ability | H11: 6 | J11: Good Presentation and explanation of workflow
C12: Pachaiyappan, Sowmiya (S.) | D12: 4 | E12: Optimization Strategies | I12: 8 | J12: Good Presentation and explanation of workflow
D13: 5 | E13: Future Enhancements | H13: 6
E14: TOTAL SCORE | I14: =SUM(F9:I13) -> 36
A15: Hackathon GroupId | B15: Location | C15: RISER/Intern Name | D15: S.No. | E15: Evalaution Parameter | F15: Poor(Points:2) | G15: Needs Improvement (Points:4) | H15: Satisfactory(Points:6) | I15: Exceptional (Points:8) | J15: Feedback on Individual Team members | K15: Overall Feedback
A16: GroupC3 | B16: Chennai | C16: Ayswar, GSS (G.) | D16: 1 | E16: Technical Understanding | I16: 8 | J16: good technical understanding, presentaiton could be better | K16: Good in understanding of concepts. can improve presentation and documentation
C17: Devi, Dharshini S (D.) | D17: 2 | E17: Teamwork / Communication | I17: 8 | J17: good technical understanding, presentaiton could be better
C18: Narayanan, Vignesh (V.) | D18: 3 | E18: Testing ability | H18: 6 | J18: good technical understanding, presentaiton could be better
C19: Mariyan, Bavith (B.) | D19: 4 | E19: Optimization Strategies | H19: 6 | J19: good technical understanding, presentaiton could be better
D20: 5 | E20: Future Enhancements | H20: 6
E21: TOTAL SCORE | I21: =SUM(F16:I20) -> 34
A22: Hackathon GroupId | B22: Location | C22: RISER/Intern Name | D22: S.No. | E22: Evalaution Parameter | F22: Poor(Points:2) | G22: Needs Improvement (Points:4) | H22: Satisfactory(Points:6) | I22: Exceptional (Points:8) | J22: Feedback on Individual Team members | K22: Overall Feedback
A23: GroupC4 | B23: Chennai | C23: Suresh, Chidambaram (C.) | D23: 1 | E23: Technical Understanding | I23: 8 | J23: Good Communication and presentation and understanding of feature | K23: good in understanding and communicaiton
C24: Senthilkumar, Sangavi (S.) | D24: 2 | E24: Teamwork / Communication | I24: 8 | J24: Good Communication and presentation and understanding of feature
C25: Subburaj, Vijay (V.A.) | D25: 3 | E25: Testing ability | H25: 6 | J25: Good Communication and presentation and understanding of feature
C26: Esther, Sherina (S.) | D26: 4 | E26: Optimization Strategies | H26: 6 | J26: Good Communication and presentation and understanding of feature
D27: 5 | E27: Future Enhancements | H27: 6
E28: TOTAL SCORE | I28: =SUM(F23:I27) -> 34
A29: Hackathon GroupId | B29: Location | C29: RISER/Intern Name | D29: S.No. | E29: Evalaution Parameter | F29: Poor(Points:2) | G29: Needs Improvement (Points:4) | H29: Satisfactory(Points:6) | I29: Exceptional (Points:8) | J29: good technical understanding and presentaiton. | K29: Overall Feedback
A30: GroupC5 | B30: Chennai | C30: Nawin, Gnana (G.) | D30: 1 | E30: Technical Understanding | I30: 8 | J30: Good technical understanding and rpesentation. | K30: Good presentation and technical understanding. strong in concepts and use of Gen AI tool
C31: Satpathy, Pritam (P.) | D31: 2 | E31: Teamwork / Communication | H31: 6 | J31: good technical understanding and programming
C32: Geetha Ragunath, Aakash (A.) | D32: 3 | E32: Testing ability | I32: 8 | J32: Good technical understanding and rpesentation.
C33: Velumani, Mathimalar (M.) | D33: 4 | E33: Optimization Strategies | H33: 6 | J33: Good technical understanding and rpesentation.
D34: 5 | E34: Future Enhancements | I34: 8
E35: TOTAL SCORE | I35: =SUM(F30:I34) -> 36
A36: Hackathon GroupId | B36: Location | C36: RISER/Intern Name | D36: S.No. | E36: Evalaution Parameter | F36: Poor(Points:2) | G36: Needs Improvement (Points:4) | H36: Satisfactory(Points:6) | I36: Exceptional (Points:8) | J36: Feedback on Individual Team members | K36: Overall Feedback
A37: GroupC6 | B37: Chennai | C37: Mennakshi Sundaram, Prathik (P.) | D37: 1 | E37: Technical Understanding | I37: 8 | J37: Good presentation, Missing team collaboration, HTML report was good for test execution | K37: Missing team collaboration, HTML report was good
C38: Gopal, Sai (S.A.) | D38: 2 | E38: Teamwork / Communication | H38: 6 | J38: Good presentation, Missing team collaboration, HTML report was good for test execution
C39: Subramaniam, Hemanth (H.) | D39: 3 | E39: Testing ability | I39: 8 | J39: Good presentation, Missing team collaboration, HTML report was good for test execution
C40: Asokan, Swasthika (S.) | D40: 4 | E40: Optimization Strategies | H40: 6 | J40: Good presentation, Missing team collaboration, HTML report was good for test execution
...

Sheet Testcases evaluation
A1: Rank | B1: Group Name | C1: Score % | D1: Checks Passed | E1: Checks Total | F1: Files in ZIP | G1: Status
A2: 🥇 1 | B2: GroupC1 | C2: 100% | D2: 42 | E2: 42 | F2: 18 | G2: ✅ Pass
A3: 12 | B3: GroupC10 | C3: 86% | D3: 34 | E3: 42 | F3: 15 | G3: ✅ Pass
A4: 🥈 2 | B4: GroupC11 | C4: 98% | D4: 41 | E4: 42 | F4: 27 | G4: ✅ Pass
A5: 6 | B5: GroupC12 | C5: 94% | D5: 39 | E5: 42 | F5: 42 | G5: ✅ Pass
A6: 5 | B6: GroupC13 | C6: 96% | D6: 37 | E6: 42 | F6: 24 | G6: ✅ Pass
A7: 8 | B7: GroupC14 | C7: 90% | D7: 35 | E7: 42 | F7: 50 | G7: ✅ Pass
A8: 13 | B8: GroupC15 | C8: 82% | D8: 33 | E8: 42 | F8: 21 | G8: ✅ Pass
A9: 14 | B9: GroupC16 | C9: 82% | D9: 33 | E9: 42 | F9: 15 | G9: ✅ Pass
A10: 17 | B10: GroupC17 | C10: 0.7 | D10: 27 | E10: 42 | F10: 14 | G10: ✅ Pass
A11: 🥉 3 | B11: GroupC2 | C11: 96% | D11: 38 | E11: 42 | F11: 14 | G11: ✅ Pass
A12: 15 | B12: GroupC3 | C12: 80% | D12: 32 | E12: 42 | F12: 18 | G12: ✅ Pass
A13: 11 | B13: GroupC4 | C13: 88% | D13: 36 | E13: 42 | F13: 14 | G13: ✅ Pass
A14: 4 | B14: GroupC5 | C14: 96% | D14: 40 | E14: 42 | F14: 15 | G14: ✅ Pass
A15: 9 | B15: GroupC6 | C15: 90% | D15: 36 | E15: 42 | F15: 18 | G15: ✅ Pass
A16: 16 | B16: GroupC7 | C16: 73% | D16: 29 | E16: 42 | F16: 14 | G16: ✅ Pass
A17: 10 | B17: GroupC8 | C17: 88% | D17: 35 | E17: 42 | F17: 14 | G17: ✅ Pass
A18: 7 | B18: GroupC9 | C18: 91% | D18: 35 | E18: 42 | F18: 44 | G18: ✅ Pass
